Workbook

Sheet Oct-23
A1: EMP_AREA_CODE | B1: EMP_REG_SERIAL_NO | C1: EMP_SUB_AREA_CODE | D1: Name | E1: EOBI_NO | F1: CNIC | G1: NIC | H1: DOB | I1: DOJ | J1: DOE | K1: NO_OF_DAYS_WORKED | L1: From_Date | M1: To_Date | N1: Payment | O1: Employer Contribution | P1: Total EOBI
A2: FAA | B2: 4320 | C2: FS | D2: Aamir Nawaz | E2: 4700E637868 | F2: 14301-7981096-7 | H2: 32933 | I2: 45166 | K2: =MAX(0, MIN(M2, J2) - MAX(L2, I2) + 1) -> 31 | L2: 45200 | M2: 45230 | N2: =ROUNDUP(K2/31*320,0) -> 320 | O2: =N2*5 -> 1600 | P2: =N2+O2 -> 1920
A3: FAA | B3: 4320 | C3: FS | D3: Abdullah Bin Rashid | E3: 4700A705194 | F3: 61101-3101618-7 | H3: 36358 | I3: 45027 | K3: =MAX(0, MIN(M3, J3) - MAX(L3, I3) + 1) -> 31 | L3: 45200 | M3: 45230 | N3: =ROUNDUP(K3/31*320,0) -> 320 | O3: =N3*5 -> 1600 | P3: =N3+O3 -> 1920
A4: FAA | B4: 4320 | C4: FS | D4: Abdullah Rasheed | E4: 4700G688671 | F4: 37401-7271621-7 | H4: 36860 | I4: 45124 | K4: =MAX(0, MIN(M4, J4) - MAX(L4, I4) + 1) -> 31 | L4: 45200 | M4: 45230 | N4: =ROUNDUP(K4/31*320,0) -> 320 | O4: =N4*5 -> 1600 | P4: =N4+O4 -> 1920
A5: FAA | B5: 4320 | C5: FS | D5: Abeera Shah | E5: 4700C706554 | F5: 61101-5688667-0 | H5: 36257 | I5: 45019 | K5: =MAX(0, MIN(M5, J5) - MAX(L5, I5) + 1) -> 31 | L5: 45200 | M5: 45230 | N5: =ROUNDUP(K5/31*320,0) -> 320 | O5: =N5*5 -> 1600 | P5: =N5+O5 -> 1920
A6: FAA | B6: 4320 | C6: FS | D6: Ahmad Hassan | E6: 4600D315335 | F6: 37405-4246562-3 | H6: 35997 | I6: 45061 | K6: =MAX(0, MIN(M6, J6) - MAX(L6, I6) + 1) -> 31 | L6: 45200 | M6: 45230 | N6: =ROUNDUP(K6/31*320,0) -> 320 | O6: =N6*5 -> 1600 | P6: =N6+O6 -> 1920
A7: FAA | B7: 4320 | C7: FS | D7: Ali Aziz | E7: 4700J723957 | F7: 81202-8426576-7 | H7: 35053 | I7: 45173 | K7: =MAX(0, MIN(M7, J7) - MAX(L7, I7) + 1) -> 31 | L7: 45200 | M7: 45230 | N7: =ROUNDUP(K7/31*320,0) -> 320 | O7: =N7*5 -> 1600 | P7: =N7+O7 -> 1920
A8: FAA | B8: 4320 | C8: FS | D8: Ali Nawaz Channa | E8: 0800E397265 | F8: 42201-8465990-5 | H8: 33408 | I8: 45078 | K8: =MAX(0, MIN(M8, J8) - MAX(L8, I8) + 1) -> 31 | L8: 45200 | M8: 45230 | N8: =ROUNDUP(K8/31*320,0) -> 320 | O8: =N8*5 -> 1600 | P8: =N8+O8 -> 1920
A9: FAA | B9: 4320 | C9: FS | D9: Alina Mubarik | E9: 4700C710820 | F9: 61101-5318332-4 | H9: 35983 | I9: 45082 | K9: =MAX(0, MIN(M9, J9) - MAX(L9, I9) + 1) -> 31 | L9: 45200 | M9: 45230 | N9: =ROUNDUP(K9/31*320,0) -> 320 | O9: =N9*5 -> 1600 | P9: =N9+O9 -> 1920
A10: FAA | B10: 4320 | C10: FS | D10: Amais Sheikh | E10: 4700D606664 | F10: 37405-5578644-1 | H10: 34684 | I10: 44958 | K10: =MAX(0, MIN(M10, J10) - MAX(L10, I10) + 1) -> 31 | L10: 45200 | M10: 45230 | N10: =ROUNDUP(K10/31*320,0) -> 320 | O10: =N10*5 -> 1600 | P10: =N10+O10 -> 1920
A11: FAA | B11: 4320 | C11: FS | D11: Asim Latif | E11: 4700A658224 | F11: 33302-5158556-5 | H11: 37370 | I11: 44739 | K11: =MAX(0, MIN(M11, J11) - MAX(L11, I11) + 1) -> 31 | L11: 45200 | M11: 45230 | N11: =ROUNDUP(K11/31*320,0) -> 320 | O11: =N11*5 -> 1600 | P11: =N11+O11 -> 1920
A12: FAA | B12: 4320 | C12: FS | D12: Atif Nawaz | E12: 4700E740695 | F12: 38404-7428636-7 | H12: 36399 | I12: 45229 | K12: =MAX(0, MIN(M12, J12) - MAX(L12, I12) + 1) -> 2 | L12: 45200 | M12: 45230 | N12: =ROUNDUP(K12/31*320,0) -> 21 | O12: =N12*5 -> 105 | P12: =N12+O12 -> 126
A13: FAA | B13: 4320 | C13: FS | D13: Basit Afraz | E13: 4700C703310 | F13: 37405-8019865-5 | H13: 34601 | I13: 44986 | K13: =MAX(0, MIN(M13, J13) - MAX(L13, I13) + 1) -> 31 | L13: 45200 | M13: 45230 | N13: =ROUNDUP(K13/31*320,0) -> 320 | O13: =N13*5 -> 1600 | P13: =N13+O13 -> 1920
... A20: FAA | B20: 4320 | C20: FS | D20: Jalees Mukarram | E20: 4700G638367 | F20: 31201-9892348-9 | H20: 37210 | I20: 44125 | K20: =MAX(0, MIN(M20, J20) - MAX(L20, I20) + 1) -> 31 | L20: 45200 | M20: 45230 | N20: =ROUNDUP(K20/31*320,0) -> 320 | O20: =N20*5 -> 1600 | P20: =N20+O20 -> 1920
A21: FAA | B21: 4320 | C21: FS | D21: Javeria Sadia | E21: 0600F209061 | F21: 42101-5324187-2 | H21: 35483 | I21: 45043 | J21: 45230 | K21: =MAX(0, MIN(M21, J21) - MAX(L21, I21) + 1) -> 31 | L21: 45200 | M21: 45230 | N21: =ROUNDUP(K21/31*320,0) -> 320 | O21: =N21*5 -> 1600 | P21: =N21+O21 -> 1920
A22: FAA | B22: 4320 | C22: FS | D22: Khadija Umer | E22: 4700A710848 | F22: 31202-4982058-2 | H22: 36401 | I22: 45096 | K22: =MAX(0, MIN(M22, J22) - MAX(L22, I22) + 1) -> 31 | L22: 45200 | M22: 45230 | N22: =ROUNDUP(K22/31*320,0) -> 320 | O22: =N22*5 -> 1600 | P22: =N22+O22 -> 1920
A23: FAA | B23: 4320 | C23: FS | D23: Laiba Imran | E23: 4700H684977 | F23: 37405-8102020-8 | H23: 36113 | I23: 44866 | K23: =MAX(0, MIN(M23, J23) - MAX(L23, I23) + 1) -> 31 | L23: 45200 | M23: 45230 | N23: =ROUNDUP(K23/31*320,0) -> 320 | O23: =N23*5 -> 1600 | P23: =N23+O23 -> 1920
A24: FAA | B24: 4320 | C24: FS | D24: Mahnoor Farhan khokhar | E24: 4700E720946 | F24: 61101-9447970-2 | H24: 36318 | I24: 45139 | J24: 45224 | K24: =MAX(0, MIN(M24, J24) - MAX(L24, I24) + 1) -> 25 | L24: 45200 | M24: 45230 | N24: =ROUNDUP(K24/31*320,0) -> 259 | O24: =N24*5 -> 1295 | P24: =N24+O24 -> 1554
A25: FAA | B25: 4320 | C25: FS | D25: Mohammad Ehtasham Balland | E25: 4700D711914 | F25: 36302-5494206-1 | H25: 33737 | I25: 45139 | K25: =MAX(0, MIN(M25, J25) - MAX(L25, I25) + 1) -> 31 | L25: 45200 | M25: 45230 | N25: =ROUNDUP(K25/31*320,0) -> 320 | O25: =N25*5 -> 1600 | P25: =N25+O25 -> 1920
A26: FAA | B26: 4320 | C26: FS | D26: Muaaz Arshad | E26: 4100C164358 | F26: 34101-0197233-1 | H26: 33917 | I26: 45166 | K26: =MAX(0, MIN(M26, J26) - MAX(L26, I26) + 1) -> 31 | L26: 45200 | M26: 45230 | N26: =ROUNDUP(K26/31*320,0) -> 320 | O26: =N26*5 -> 1600 | P26: =N26+O26 -> 1920
A27: FAA | B27: 4320 | C27: FS | D27: Muhaimin Khan | E27: 4700E763936 | F27: 34101-6716758-6 | H27: 36502 | I27: 45098 | K27: =MAX(0, MIN(M27, J27) - MAX(L27, I27) + 1) -> 31 | L27: 45200 | M27: 45230 | N27: =ROUNDUP(K27/31*320,0) -> 320 | O27: =N27*5 -> 1600 | P27: =N27+O27 -> 1920
A28: FAA | B28: 4320 | C28: FS | D28: Muhammad Abdullah Salam | E28: 4700G697010 | F28: 17301-7752570-9 | H28: 36690 | I28: 44938 | K28: =MAX(0, MIN(M28, J28) - MAX(L28, I28) + 1) -> 31 | L28: 45200 | M28: 45230 | N28: =ROUNDUP(K28/31*320,0) -> 320 | O28: =N28*5 -> 1600 | P28: =N28+O28 -> 1920
A29: FAA | B29: 4320 | C29: FS | D29: Muhammad Abubakar | E29: 4700H723959 | F29: 35201-8046049-1 | H29: 37240 | I29: 45176 | K29: =MAX(0, MIN(M29, J29) - MAX(L29, I29) + 1) -> 31 | L29: 45200 | M29: 45230 | N29: =ROUNDUP(K29/31*320,0) -> 320 | O29: =N29*5 -> 1600 | P29: =N29+O29 -> 1920
A30: FAA | B30: 4320 | C30: FS | D30: Muhammad Adnan | E30: 4700A638371 | F30: 54401-7578020-9 | H30: 33240 | I30: 44290 | J30: 45230 | K30: =MAX(0, MIN(M30, J30) - MAX(L30, I30) + 1) -> 31 | L30: 45200 | M30: 45230 | N30: =ROUNDUP(K30/31*320,0) -> 320 | O30: =N30*5 -> 1600 | P30: =N30+O30 -> 1920
A31: FAA | B31: 4320 | C31: FS | D31: Muhammad Arham | E31: 4700J673932 | F31: 36103-7439746-1 | H31: 37136 | I31: 45201 | K31: =MAX(0, MIN(M31, J31) - MAX(L31, I31) + 1) -> 30 | L31: 45200 | M31: 45230 | N31: =ROUNDUP(K31/31*320,0) -> 310 | O31: =N31*5 -> 1550 | P31: =N31+O31 -> 1860
A32: FAA | B32: 4320 | C32: FS | D32: Muhammad Asadullah Shahid | E32: 4700G581544 | F32: 36603-1234883-1 | H32: 35943 | I32: 45215 | K32: =MAX(0, MIN(M32, J32) - MAX(L32, I32) + 1) -> 16 | L32: 45200 | M32: 45230 | N32: =ROUNDUP(K32/31*320,0) -> 166 | O32: =N32*5 -> 830 | P32: =N32+O32 -> 996
A33: FAA | B33: 4320 | C33: FS | D33: Muhammad Hammad Maqsood | E33: 4700A703312 | F33: 37405-2794891-9 | H33: 36898 | I33: 44988 | K33: =MAX(0, MIN(M33, J33) - MAX(L33, I33) + 1) -> 31 | L33: 45200 | M33: 45230 | N33: =ROUNDUP(K33/31*320,0) -> 320 | O33: =N33*5 -> 1600 | P33: =N33+O33 -> 1920
A34: FAA | B34: 4320 | C34: FS | D34: Muhammad Hamza | E34: 4600F317513 | F34: 61101-4668132-7 | H34: 35159 | I34: 45078 | K34: =MAX(0, MIN(M34, J34) - MAX(L34, I34) + 1) -> 31 | L34: 45200 | M34: 45230 | N34: =ROUNDUP(K34/31*320,0) -> 320 | O34: =N34*5 -> 1600 | P34: =N34+O34 -> 1920
A35: FAA | B35: 4320 | C35: FS | D35: Muhammad Haris Gul | E35: 4700I638373 | F35: 61101-3389194-7 | H35: 36029 | I35: 45068 | J35: 45207 | K35: =MAX(0, MIN(M35, J35) - MAX(L35, I35) + 1) -> 8 | L35: 45200 | M35: 45230 | N35: =ROUNDUP(K35/31*320,0) -> 83 | O35: =N35*5 -> 415 | P35: =N35+O35 -> 498
A36: FAA | B36: 4320 | C36: FS | D36: Muhammad Hassan Shakeel | E36: 4700H690431 | F36: 35402-2593513-5 | H36: 36794 | I36: 44915 | K36: =MAX(0, MIN(M36, J36) - MAX(L36, I36) + 1) -> 31 | L36: 45200 | M36: 45230 | N36: =ROUNDUP(K36/31*320,0) -> 320 | O36: =N36*5 -> 1600 | P36: =N36+O36 -> 1920
A37: FAA | B37: 4320 | C37: FS | D37: Muhammad Ibrahim | E37: 4700C720948 | F37: 31101-0776303-7 | H37: 37149 | I37: 45124 | K37: =MAX(0, MIN(M37, J37) - MAX(L37, I37) + 1) -> 31 | L37: 45200 | M37: 45230 | N37: =ROUNDUP(K37/31*320,0) -> 320 | O37: =N37*5 -> 1600 | P37: =N37+O37 -> 1920
A38: FAA | B38: 4320 | C38: FS | D38: Muhammad Mutahhar | E38: 3300E326308 | F38: 42301-3092028-3 | H38: 35767 | I38: 45117 | K38: =MAX(0, MIN(M38, J38) - MAX(L38, I38) + 1) -> 31 | L38: 45200 | M38: 45230 | N38: =ROUNDUP(K38/31*320,0) -> 320 | O38: =N38*5 -> 1600 | P38: =N38+O38 -> 1920
A39: FAA | B39: 4320 | C39: FS | D39: Muhammad Saad Tariq | E39: 4700D679730 | F39: 61101-0817777-7 | H39: 36207 | I39: 45054 | K39: =MAX(0, MIN(M39, J39) - MAX(L39, I39) + 1) -> 31 | L39: 45200 | M39: 45230 | N39: =ROUNDUP(K39/31*320,0) -> 320 | O39: =N39*5 -> 1600 | P39: =N39+O39 -> 1920
A40: FAA | B40: 4320 | C40: FS | D40: Muhammad Umair | E40: 4700A700796 | F40: 42501-3911861-7 | H40: 36480 | I40: 44970 | K40: =MAX(0, MIN(M40, 'Nov-23'!J39) - MAX(L40, I40) + 1) -> 31 | L40: 45200 | M40: 45230 | N40: =ROUNDUP(K40/31*320,0) -> 320 | O40: =N40*5 -> 1600 | P40: =N40+O40 -> 1920
A41: FAA | B41: 4320 | C41: FS | D41: Muhammad Wajahat | E41: 4700A618216 | F41: 32203-2007547-1 | H41: 36768 | I41: 44888 | K41: =MAX(0, MIN(M41, J41) - MAX(L41, I41) + 1) -> 31 | L41: 45200 | M41: 45230 | N41: =ROUNDUP(K41/31*320,0) -> 320 | O41: =N41*5 -> 1600 | P41: =N41+O41 -> 1920
A42: FAA | B42: 4320 | C42: FS | D42: Muhammad Waleed Imran | E42: 4700J724945 | F42: 35201-8352529-1 | H42: 36074 | I42: 45180 | K42: =MAX(0, MIN(M42, J42) - MAX(L42, I42) + 1) -> 31 | L42: 45200 | M42: 45230 | N42: =ROUNDUP(K42/31*320,0) -> 320 | O42: =N42*5 -> 1600 | P42: =N42+O42 -> 1920
A43: FAA | B43: 4320 | C43: FS | D43: Muhammad Zahab Ahmed | E43: 3600G329844 | F43: 31102-2135283-9 | H43: 34300 | I43: 45183 | K43: =MAX(0, MIN(M43, J43) - MAX(L43, I43) + 1) -> 31 | L43: 45200 | M43: 45230 | N43: =ROUNDUP(K43/31*320,0) -> 320 | O43: =N43*5 -> 1600 | P43: =N43+O43 -> 1920
A44: FAA | B44: 4320 | C44: FS | D44: Muhammad Zaid | E44: 4700B667971 | F44: 42000-5973098-1 | H44: 36118 | I44: 44783 | K44: =MAX(0, MIN(M44, J44) - MAX(L44, I44) + 1) -> 31 | L44: 45200 | M44: 45230 | N44: =ROUNDUP(K44/31*320,0) -> 320 | O44: =N44*5 -> 1600 | P44: =N44+O44 -> 1920
A45: FAA | B45: 4320 | C45: FS | D45: Naimal Imran | E45: 4700J662127 | F45: 35202-0754928-4 | H45: 36541 | I45: 44755 | K45: =MAX(0, MIN(M45, J45) - MAX(L45, I45) + 1) -> 31 | L45: 45200 | M45: 45230 | N45: =ROUNDUP(K45/31*320,0) -> 320 | O45: =N45*5 -> 1600 | P45: =N45+O45 -> 1920
A46: FAA | B46: 4320 | C46: FS | D46: Namra Akram | E46: 4700F444303 | F46: 61101-4919576-8 | H46: 34335 | I46: 45078 | K46: =MAX(0, MIN(M46, J46) - MAX(L46, I46) + 1) -> 31 | L46: 45200 | M46: 45230 | N46: =ROUNDUP(K46/31*320,0) -> 320 | O46: =N46*5 -> 1600 | P46: =N46+O46 -> 1920
...

Sheet Nov-23
A1: EMP_AREA_CODE | B1: EMP_REG_SERIAL_NO | C1: EMP_SUB_AREA_CODE | D1: Name | E1: EOBI_NO | F1: CNIC | G1: NIC | H1: DOB | I1: DOJ | J1: DOE | K1: NO_OF_DAYS_WORKED | L1: From_Date | M1: To_Date | N1: Payment | O1: Employer Contribution | P1: Total EOBI
A2: FAA | B2: 4320 | C2: FS | D2: Aamir Nawaz | E2: 4700E637868 | F2: 14301-7981096-7 | H2: 32933 | I2: 45166 | K2: =MAX(0, MIN(M2, J2) - MAX(L2, I2) + 1) -> 30 | L2: 45231 | M2: 45260 | N2: =ROUNDUP(K2/30*320,0) -> 320 | O2: =N2*5 -> 1600 | P2: =N2+O2 -> 1920
A3: FAA | B3: 4320 | C3: FS | D3: Abdullah Bin Rashid | E3: 4700A705194 | F3: 61101-3101618-7 | H3: 36358 | I3: 45027 | K3: =MAX(0, MIN(M3, J3) - MAX(L3, I3) + 1) -> 30 | L3: 45231 | M3: 45260 | N3: =ROUNDUP(K3/30*320,0) -> 320 | O3: =N3*5 -> 1600 | P3: =N3+O3 -> 1920
A4: FAA | B4: 4320 | C4: FS | D4: Abdullah Rasheed | E4: 4700G688671 | F4: 37401-7271621-7 | H4: 36860 | I4: 45124 | K4: =MAX(0, MIN(M4, J4) - MAX(L4, I4) + 1) -> 30 | L4: 45231 | M4: 45260 | N4: =ROUNDUP(K4/30*320,0) -> 320 | O4: =N4*5 -> 1600 | P4: =N4+O4 -> 1920
A5: FAA | B5: 4320 | C5: FS | D5: Abeera Shah | E5: 4700C706554 | F5: 61101-5688667-0 | H5: 36257 | I5: 45019 | J5: 45260 | K5: =MAX(0, MIN(M5, J5) - MAX(L5, I5) + 1) -> 30 | L5: 45231 | M5: 45260 | N5: =ROUNDUP(K5/30*320,0) -> 320 | O5: =N5*5 -> 1600 | P5: =N5+O5 -> 1920
A6: FAA | B6: 4320 | C6: FS | D6: Ahmad Hassan | E6: 4600D315335 | F6: 37405-4246562-3 | H6: 35997 | I6: 45061 | K6: =MAX(0, MIN(M6, J6) - MAX(L6, I6) + 1) -> 30 | L6: 45231 | M6: 45260 | N6: =ROUNDUP(K6/30*320,0) -> 320 | O6: =N6*5 -> 1600 | P6: =N6+O6 -> 1920
A7: FAA | B7: 4320 | C7: FS | D7: Ali Aziz | E7: 4700J723957 | F7: 81202-8426576-7 | H7: 35053 | I7: 45173 | K7: =MAX(0, MIN(M7, J7) - MAX(L7, I7) + 1) -> 30 | L7: 45231 | M7: 45260 | N7: =ROUNDUP(K7/30*320,0) -> 320 | O7: =N7*5 -> 1600 | P7: =N7+O7 -> 1920
A8: FAA | B8: 4320 | C8: FS | D8: Ali Irfan | E8: 3100J940197 | F8: 35202-7336402-9 | H8: 36634 | I8: 45251 | K8: =MAX(0, MIN(M8, J8) - MAX(L8, I8) + 1) -> 10 | L8: 45231 | M8: 45260 | N8: =ROUNDUP(K8/30*320,0) -> 107 | O8: =N8*5 -> 535 | P8: =N8+O8 -> 642
A9: FAA | B9: 4320 | C9: FS | D9: Ali Nawaz Channa | E9: 0800E397265 | F9: 42201-8465990-5 | H9: 33408 | I9: 45078 | K9: =MAX(0, MIN(M9, J9) - MAX(L9, I9) + 1) -> 30 | L9: 45231 | M9: 45260 | N9: =ROUNDUP(K9/30*320,0) -> 320 | O9: =N9*5 -> 1600 | P9: =N9+O9 -> 1920
A10: FAA | B10: 4320 | C10: FS | D10: Alina Mubarik | E10: 4700C710820 | F10: 61101-5318332-4 | H10: 35983 | I10: 45082 | K10: =MAX(0, MIN(M10, J10) - MAX(L10, I10) + 1) -> 30 | L10: 45231 | M10: 45260 | N10: =ROUNDUP(K10/30*320,0) -> 320 | O10: =N10*5 -> 1600 | P10: =N10+O10 -> 1920
A11: FAA | B11: 4320 | C11: FS | D11: Altamash Shaban | E11: 4700G469815 | F11: 37405-5322814-9 | H11: 33048 | I11: 45250 | K11: =MAX(0, MIN(M11, J11) - MAX(L11, I11) + 1) -> 11 | L11: 45231 | M11: 45260 | N11: =ROUNDUP(K11/30*320,0) -> 118 | O11: =N11*5 -> 590 | P11: =N11+O11 -> 708
A12: FAA | B12: 4320 | C12: FS | D12: Amais Sheikh | E12: 4700D606664 | F12: 37405-5578644-1 | H12: 34684 | I12: 44958 | J12: 45256 | K12: =MAX(0, MIN(M12, J12) - MAX(L12, I12) + 1) -> 26 | L12: 45231 | M12: 45260 | N12: =ROUNDUP(K12/30*320,0) -> 278 | O12: =N12*5 -> 1390 | P12: =N12+O12 -> 1668
A13: FAA | B13: 4320 | C13: FS | D13: Asim Latif | E13: 4700A658224 | F13: 33302-5158556-5 | H13: 37370 | I13: 44739 | K13: =MAX(0, MIN(M13, J13) - MAX(L13, I13) + 1) -> 30 | L13: 45231 | M13: 45260 | N13: =ROUNDUP(K13/30*320,0) -> 320 | O13: =N13*5 -> 1600 | P13: =N13+O13 -> 1920
A14: FAA | B14: 4320 | C14: FS | D14: Atif Nawaz | E14: 4700E740695 | F14: 38404-7428636-7 | H14: 36399 | I14: 45229 | K14: =MAX(0, MIN(M14, J14) - MAX(L14, I14) + 1) -> 30 | L14: 45231 | M14: 45260 | N14: =ROUNDUP(K14/30*320,0) -> 320 | O14: =N14*5 -> 1600 | P14: =N14+O14 -> 1920
A15: FAA | B15: 4320 | C15: FS | D15: Basit Afraz | E15: 4700C703310 | F15: 37405-8019865-5 | H15: 34601 | I15: 44986 | K15: =MAX(0, MIN(M15, J15) - MAX(L15, I15) + 1) -> 30 | L15: 45231 | M15: 45260 | N15: =ROUNDUP(K15/30*320,0) -> 320 | O15: =N15*5 -> 1600 | P15: =N15+O15 -> 1920
A16: FAA | B16: 4320 | C16: FS | D16: Elaf Hassan | E16: 4700I723958 | F16: 36302-4009333-7 | H16: 37244 | I16: 45173 | K16: =MAX(0, MIN(M16, J16) - MAX(L16, I16) + 1) -> 30 | L16: 45231 | M16: 45260 | N16: =ROUNDUP(K16/30*320,0) -> 320 | O16: =N16*5 -> 1600 | P16: =N16+O16 -> 1920
A17: FAA | B17: 4320 | C17: FS | D17: Faizan Khan | E17: 4700C662124 | F17: 16204-0388636-3 | H17: 35704 | I17: 44760 | K17: =MAX(0, MIN(M17, J17) - MAX(L17, I17) + 1) -> 30 | L17: 45231 | M17: 45260 | N17: =ROUNDUP(K17/30*320,0) -> 320 | O17: =N17*5 -> 1600 | P17: =N17+O17 -> 1920
A18: FAA | B18: 4320 | C18: FS | D18: Hamza Ahmad | E18: 4700I678608 | F18: 37405-6689341-9 | H18: 36246 | I18: 44851 | K18: =MAX(0, MIN(M18, J18) - MAX(L18, I18) + 1) -> 30 | L18: 45231 | M18: 45260 | N18: =ROUNDUP(K18/30*320,0) -> 320 | O18: =N18*5 -> 1600 | P18: =N18+O18 -> 1920
A19: FAA | B19: 4320 | C19: FS | D19: Hamza Ali Khan | E19: 4700B690429 | F19: 37405-5700118-7 | H19: 35606 | I19: 44896 | K19: =MAX(0, MIN(M19, J19) - MAX(L19, I19) + 1) -> 30 | L19: 45231 | M19: 45260 | N19: =ROUNDUP(K19/30*320,0) -> 320 | O19: =N19*5 -> 1600 | P19: =N19+O19 -> 1920
A20: FAA | B20: 4320 | C20: FS | D20: Hira Farooq | E20: 4700B703311 | F20: 61101-2625195-8 | H20: 34973 | I20: 44986 | K20: =MAX(0, MIN(M20, J20) - MAX(L20, I20) + 1) -> 30 | L20: 45231 | M20: 45260 | N20: =ROUNDUP(K20/30*320,0) -> 320 | O20: =N20*5 -> 1600 | P20: =N20+O20 -> 1920
A21: FAA | B21: 4320 | C21: FS | D21: Ibrahim Shah | E21: 4700G658260 | F21: 35201-2147689-9 | H21: 36891 | I21: 44739 | K21: =MAX(0, MIN(M21, J21) - MAX(L21, I21) + 1) -> 30 | L21: 45231 | M21: 45260 | N21: =ROUNDUP(K21/30*320,0) -> 320 | O21: =N21*5 -> 1600 | P21: =N21+O21 -> 1920
A22: FAA | B22: 4320 | C22: FS | D22: Jalees Mukarram | E22: 4700G638367 | F22: 31201-9892348-9 | H22: 37210 | I22: 44125 | K22: =MAX(0, MIN(M22, J22) - MAX(L22, I22) + 1) -> 30 | L22: 45231 | M22: 45260 | N22: =ROUNDUP(K22/30*320,0) -> 320 | O22: =N22*5 -> 1600 | P22: =N22+O22 -> 1920
A23: FAA | B23: 4320 | C23: FS | D23: Khadija Umer | E23: 4700A710848 | F23: 31202-4982058-2 | H23: 36401 | I23: 45096 | K23: =MAX(0, MIN(M23, J23) - MAX(L23, I23) + 1) -> 30 | L23: 45231 | M23: 45260 | N23: =ROUNDUP(K23/30*320,0) -> 320 | O23: =N23*5 -> 1600 | P23: =N23+O23 -> 1920
A24: FAA | B24: 4320 | C24: FS | D24: Laiba Imran | E24: 4700H684977 | F24: 37405-8102020-8 | H24: 36113 | I24: 44866 | K24: =MAX(0, MIN(M24, J24) - MAX(L24, I24) + 1) -> 30 | L24: 45231 | M24: 45260 | N24: =ROUNDUP(K24/30*320,0) -> 320 | O24: =N24*5 -> 1600 | P24: =N24+O24 -> 1920
... A26: FAA | B26: 4320 | C26: FS | D26: Muaaz Arshad | E26: 4100C164358 | F26: 34101-0197233-1 | H26: 33917 | I26: 45166 | K26: =MAX(0, MIN(M26, J26) - MAX(L26, I26) + 1) -> 30 | L26: 45231 | M26: 45260 | N26: =ROUNDUP(K26/30*320,0) -> 320 | O26: =N26*5 -> 1600 | P26: =N26+O26 -> 1920
A27: FAA | B27: 4320 | C27: FS | D27: Muhaimin Khan | E27: 4700E763936 | F27: 34101-6716758-6 | H27: 36502 | I27: 45098 | J27: 45246 | K27: =MAX(0, MIN(M27, J27) - MAX(L27, I27) + 1) -> 16 | L27: 45231 | M27: 45260 | N27: =ROUNDUP(K27/30*320,0) -> 171 | O27: =N27*5 -> 855 | P27: =N27+O27 -> 1026
A28: FAA | B28: 4320 | C28: FS | D28: Muhammad Abdullah Salam | E28: 4700G697010 | F28: 17301-7752570-9 | H28: 36690 | I28: 44938 | K28: =MAX(0, MIN(M28, J28) - MAX(L28, I28) + 1) -> 30 | L28: 45231 | M28: 45260 | N28: =ROUNDUP(K28/30*320,0) -> 320 | O28: =N28*5 -> 1600 | P28: =N28+O28 -> 1920
A29: FAA | B29: 4320 | C29: FS | D29: Muhammad Abubakar | E29: 4700H723959 | F29: 35201-8046049-1 | H29: 37240 | I29: 45176 | K29: =MAX(0, MIN(M29, J29) - MAX(L29, I29) + 1) -> 30 | L29: 45231 | M29: 45260 | N29: =ROUNDUP(K29/30*320,0) -> 320 | O29: =N29*5 -> 1600 | P29: =N29+O29 -> 1920
A30: FAA | B30: 4320 | C30: FS | D30: Muhammad Arham | E30: 4700J673932 | F30: 36103-7439746-1 | H30: 37136 | I30: 45201 | K30: =MAX(0, MIN(M30, J30) - MAX(L30, I30) + 1) -> 30 | L30: 45231 | M30: 45260 | N30: =ROUNDUP(K30/30*320,0) -> 320 | O30: =N30*5 -> 1600 | P30: =N30+O30 -> 1920
A31: FAA | B31: 4320 | C31: FS | D31: Muhammad Asadullah Shahid | E31: 4700G581544 | F31: 36603-1234883-1 | H31: 35943 | I31: 45215 | K31: =MAX(0, MIN(M31, J31) - MAX(L31, I31) + 1) -> 30 | L31: 45231 | M31: 45260 | N31: =ROUNDUP(K31/30*320,0) -> 320 | O31: =N31*5 -> 1600 | P31: =N31+O31 -> 1920
A32: FAA | B32: 4320 | C32: FS | D32: Muhammad Hammad Maqsood | E32: 4700A703312 | F32: 37405-2794891-9 | H32: 36898 | I32: 44988 | K32: =MAX(0, MIN(M32, J32) - MAX(L32, I32) + 1) -> 30 | L32: 45231 | M32: 45260 | N32: =ROUNDUP(K32/30*320,0) -> 320 | O32: =N32*5 -> 1600 | P32: =N32+O32 -> 1920
A33: FAA | B33: 4320 | C33: FS | D33: Muhammad Hamza | E33: 4600F317513 | F33: 61101-4668132-7 | H33: 35159 | I33: 45078 | K33: =MAX(0, MIN(M33, J33) - MAX(L33, I33) + 1) -> 30 | L33: 45231 | M33: 45260 | N33: =ROUNDUP(K33/30*320,0) -> 320 | O33: =N33*5 -> 1600 | P33: =N33+O33 -> 1920
A34: FAA | B34: 4320 | C34: FS | D34: Muhammad Hassan Shakeel | E34: 4700H690431 | F34: 35402-2593513-5 | H34: 36794 | I34: 44915 | K34: =MAX(0, MIN(M34, J34) - MAX(L34, I34) + 1) -> 30 | L34: 45231 | M34: 45260 | N34: =ROUNDUP(K34/30*320,0) -> 320 | O34: =N34*5 -> 1600 | P34: =N34+O34 -> 1920
A35: FAA | B35: 4320 | C35: FS | D35: Muhammad Ibrahim | E35: 4700C720948 | F35: 31101-0776303-7 | H35: 37149 | I35: 45124 | K35: =MAX(0, MIN(M35, J35) - MAX(L35, I35) + 1) -> 30 | L35: 45231 | M35: 45260 | N35: =ROUNDUP(K35/30*320,0) -> 320 | O35: =N35*5 -> 1600 | P35: =N35+O35 -> 1920
A36: FAA | B36: 4320 | C36: FS | D36: Muhammad Mutahhar | E36: 3300E326308 | F36: 42301-3092028-3 | H36: 35767 | I36: 45117 | K36: =MAX(0, MIN(M36, J36) - MAX(L36, I36) + 1) -> 30 | L36: 45231 | M36: 45260 | N36: =ROUNDUP(K36/30*320,0) -> 320 | O36: =N36*5 -> 1600 | P36: =N36+O36 -> 1920
A37: FAA | B37: 4320 | C37: FS | D37: Muhammad Nabeel Asif | E37: 0800I431358 | F37: 42101-1217952-3 | H37: 34503 | I37: 45246 | K37: =MAX(0, MIN(M37, J37) - MAX(L37, I37) + 1) -> 15 | L37: 45231 | M37: 45260 | N37: =ROUNDUP(K37/30*320,0) -> 160 | O37: =N37*5 -> 800 | P37: =N37+O37 -> 960
A38: FAA | B38: 4320 | C38: FS | D38: Muhammad Saad Tariq | E38: 4700D679730 | F38: 61101-0817777-7 | H38: 36207 | I38: 45054 | K38: =MAX(0, MIN(M38, J38) - MAX(L38, I38) + 1) -> 30 | L38: 45231 | M38: 45260 | N38: =ROUNDUP(K38/30*320,0) -> 320 | O38: =N38*5 -> 1600 | P38: =N38+O38 -> 1920
A39: FAA | B39: 4320 | C39: FS | D39: Muhammad Umair | E39: 4700A700796 | F39: 42501-3911861-7 | H39: 36480 | I39: 44970 | J39: 45260 | K39: =MAX(0, MIN(M39, J39) - MAX(L39, I39) + 1) -> 30 | L39: 45231 | M39: 45260 | N39: =ROUNDUP(K39/30*320,0) -> 320 | O39: =N39*5 -> 1600 | P39: =N39+O39 -> 1920
A40: FAA | B40: 4320 | C40: FS | D40: Muhammad Wajahat | E40: 4700A618216 | F40: 32203-2007547-1 | H40: 36768 | I40: 44888 | K40: =MAX(0, MIN(M40, J40) - MAX(L40, I40) + 1) -> 30 | L40: 45231 | M40: 45260 | N40: =ROUNDUP(K40/30*320,0) -> 320 | O40: =N40*5 -> 1600 | P40: =N40+O40 -> 1920
A41: FAA | B41: 4320 | C41: FS | D41: Muhammad Waleed Imran | E41: 4700J724945 | F41: 35201-8352529-1 | H41: 36074 | I41: 45180 | J41: 45247 | K41: =MAX(0, MIN(M41, J41) - MAX(L41, I41) + 1) -> 17 | L41: 45231 | M41: 45260 | N41: =ROUNDUP(K41/30*320,0) -> 182 | O41: =N41*5 -> 910 | P41: =N41+O41 -> 1092
...

Sheet Dec-23
A1: EMP_AREA_CODE | B1: EMP_REG_SERIAL_NO | C1: EMP_SUB_AREA_CODE | D1: Name | E1: EOBI_NO | F1: CNIC | G1: NIC | H1: DOB | I1: DOJ | J1: DOE | K1: NO_OF_DAYS_WORKED | L1: From_Date | M1: To_Date | N1: Payment | O1: Employer Contribution | P1: Total EOBI
A2: FAA | B2: 4320 | C2: FS | D2: Aamir Nawaz | E2: 4700E637868 | F2: 14301-7981096-7 | H2: 32933 | I2: 45166 | J2: 45282 | K2: =MAX(0, MIN(M2, J2) - MAX(L2, I2) + 1) -> 22 | L2: 45261 | M2: 45291 | N2: =ROUNDUP(K2/31*320,0) -> 228 | O2: =N2*5 -> 1140 | P2: =N2+O2 -> 1368
A3: FAA | B3: 4320 | C3: FS | D3: Abdullah Bin Rashid | E3: 4700A705194 | F3: 61101-3101618-7 | H3: 36358 | I3: 45027 | K3: =MAX(0, MIN(M3, J3) - MAX(L3, I3) + 1) -> 31 | L3: 45261 | M3: 45291 | N3: =ROUNDUP(K3/31*320,0) -> 320 | O3: =N3*5 -> 1600 | P3: =N3+O3 -> 1920
A4: FAA | B4: 4320 | C4: FS | D4: Abdullah Rasheed | E4: 4700G688671 | F4: 37401-7271621-7 | H4: 36860 | I4: 45124 | K4: =MAX(0, MIN(M4, J4) - MAX(L4, I4) + 1) -> 31 | L4: 45261 | M4: 45291 | N4: =ROUNDUP(K4/31*320,0) -> 320 | O4: =N4*5 -> 1600 | P4: =N4+O4 -> 1920
A5: FAA | B5: 4320 | C5: FS | D5: Ahmad Hassan | E5: 4600D315335 | F5: 37405-4246562-3 | H5: 35997 | I5: 45061 | K5: =MAX(0, MIN(M5, J5) - MAX(L5, I5) + 1) -> 31 | L5: 45261 | M5: 45291 | N5: =ROUNDUP(K5/31*320,0) -> 320 | O5: =N5*5 -> 1600 | P5: =N5+O5 -> 1920
A6: FAA | B6: 4320 | C6: FS | D6: Ahmed Hussain | E6: 4800F063920 | F6: 38102-5707136-9 | H6: 36353 | I6: 45278 | K6: =MAX(0, MIN(M6, J6) - MAX(L6, I6) + 1) -> 14 | L6: 45261 | M6: 45291 | N6: =ROUNDUP(K6/31*320,0) -> 145 | O6: =N6*5 -> 725 | P6: =N6+O6 -> 870
A7: FAA | B7: 4320 | C7: FS | D7: Ali Aziz | E7: 4700J723957 | F7: 81202-8426576-7 | H7: 35053 | I7: 45173 | K7: =MAX(0, MIN(M7, J7) - MAX(L7, I7) + 1) -> 31 | L7: 45261 | M7: 45291 | N7: =ROUNDUP(K7/31*320,0) -> 320 | O7: =N7*5 -> 1600 | P7: =N7+O7 -> 1920
A8: FAA | B8: 4320 | C8: FS | D8: Ali Irfan | E8: 3100J940197 | F8: 35202-7336402-9 | H8: 36634 | I8: 45251 | K8: =MAX(0, MIN(M8, J8) - MAX(L8, I8) + 1) -> 31 | L8: 45261 | M8: 45291 | N8: =ROUNDUP(K8/31*320,0) -> 320 | O8: =N8*5 -> 1600 | P8: =N8+O8 -> 1920
A9: FAA | B9: 4320 | C9: FS | D9: Ali Nawaz Channa | E9: 0800E397265 | F9: 42201-8465990-5 | H9: 33408 | I9: 45078 | K9: =MAX(0, MIN(M9, J9) - MAX(L9, I9) + 1) -> 31 | L9: 45261 | M9: 45291 | N9: =ROUNDUP(K9/31*320,0) -> 320 | O9: =N9*5 -> 1600 | P9: =N9+O9 -> 1920
A10: FAA | B10: 4320 | C10: FS | D10: Alina Mubarik | E10: 4700C710820 | F10: 61101-5318332-4 | H10: 35983 | I10: 45082 | K10: =MAX(0, MIN(M10, J10) - MAX(L10, I10) + 1) -> 31 | L10: 45261 | M10: 45291 | N10: =ROUNDUP(K10/31*320,0) -> 320 | O10: =N10*5 -> 1600 | P10: =N10+O10 -> 1920
A11: FAA | B11: 4320 | C11: FS | D11: Altamash Shaban | E11: 4700G469815 | F11: 37405-5322814-9 | H11: 33048 | I11: 45250 | K11: =MAX(0, MIN(M11, J11) - MAX(L11, I11) + 1) -> 31 | L11: 45261 | M11: 45291 | N11: =ROUNDUP(K11/31*320,0) -> 320 | O11: =N11*5 -> 1600 | P11: =N11+O11 -> 1920
A12: FAA | B12: 4320 | C12: FS | D12: Asim Latif | E12: 4700A658224 | F12: 33302-5158556-5 | H12: 37370 | I12: 44739 | K12: =MAX(0, MIN(M12, J12) - MAX(L12, I12) + 1) -> 31 | L12: 45261 | M12: 45291 | N12: =ROUNDUP(K12/31*320,0) -> 320 | O12: =N12*5 -> 1600 | P12: =N12+O12 -> 1920
A13: FAA | B13: 4320 | C13: FS | D13: Atif Nawaz | E13: 4700E740695 | F13: 38404-7428636-7 | H13: 36399 | I13: 45229 | K13: =MAX(0, MIN(M13, J13) - MAX(L13, I13) + 1) -> 31 | L13: 45261 | M13: 45291 | N13: =ROUNDUP(K13/31*320,0) -> 320 | O13: =N13*5 -> 1600 | P13: =N13+O13 -> 1920
A14: FAA | B14: 4320 | C14: FS | D14: Basit Afraz | E14: 4700C703310 | F14: 37405-8019865-5 | H14: 34601 | I14: 44986 | K14: =MAX(0, MIN(M14, J14) - MAX(L14, I14) + 1) -> 31 | L14: 45261 | M14: 45291 | N14: =ROUNDUP(K14/31*320,0) -> 320 | O14: =N14*5 -> 1600 | P14: =N14+O14 -> 1920
A15: FAA | B15: 4320 | C15: FS | D15: Elaf Hassan | E15: 4700I723958 | F15: 36302-4009333-7 | H15: 37244 | I15: 45173 | J15: 45291 | K15: =MAX(0, MIN(M15, J15) - MAX(L15, I15) + 1) -> 31 | L15: 45261 | M15: 45291 | N15: =ROUNDUP(K15/31*320,0) -> 320 | O15: =N15*5 -> 1600 | P15: =N15+O15 -> 1920
A16: FAA | B16: 4320 | C16: FS | D16: Faiza Khan | E16: 4700J710823 | F16: 61101-0776147-2 | H16: 37322 | I16: 45261 | K16: =MAX(0, MIN(M16, J16) - MAX(L16, I16) + 1) -> 31 | L16: 45261 | M16: 45291 | N16: =ROUNDUP(K16/31*320,0) -> 320 | O16: =N16*5 -> 1600 | P16: =N16+O16 -> 1920
A17: FAA | B17: 4320 | C17: FS | D17: Faizan Khan | E17: 4700C662124 | F17: 16204-0388636-3 | H17: 35704 | I17: 44760 | K17: =MAX(0, MIN(M17, J17) - MAX(L17, I17) + 1) -> 31 | L17: 45261 | M17: 45291 | N17: =ROUNDUP(K17/31*320,0) -> 320 | O17: =N17*5 -> 1600 | P17: =N17+O17 -> 1920
A18: FAA | B18: 4320 | C18: FS | D18: Hamza Ahmad | E18: 4700I678608 | F18: 37405-6689341-9 | H18: 36246 | I18: 44851 | K18: =MAX(0, MIN(M18, J18) - MAX(L18, I18) + 1) -> 31 | L18: 45261 | M18: 45291 | N18: =ROUNDUP(K18/31*320,0) -> 320 | O18: =N18*5 -> 1600 | P18: =N18+O18 -> 1920
A19: FAA | B19: 4320 | C19: FS | D19: Hamza Ali Khan | E19: 4700B690429 | F19: 37405-5700118-7 | H19: 35606 | I19: 44896 | K19: =MAX(0, MIN(M19, J19) - MAX(L19, I19) + 1) -> 31 | L19: 45261 | M19: 45291 | N19: =ROUNDUP(K19/31*320,0) -> 320 | O19: =N19*5 -> 1600 | P19: =N19+O19 -> 1920
A20: FAA | B20: 4320 | C20: FS | D20: Hira Farooq | E20: 4700B703311 | F20: 61101-2625195-8 | H20: 34973 | I20: 44986 | K20: =MAX(0, MIN(M20, J20) - MAX(L20, I20) + 1) -> 31 | L20: 45261 | M20: 45291 | N20: =ROUNDUP(K20/31*320,0) -> 320 | O20: =N20*5 -> 1600 | P20: =N20+O20 -> 1920
A21: FAA | B21: 4320 | C21: FS | D21: Ibrahim Shah | E21: 4700G658260 | F21: 35201-2147689-9 | H21: 36891 | I21: 44739 | K21: =MAX(0, MIN(M21, J21) - MAX(L21, I21) + 1) -> 31 | L21: 45261 | M21: 45291 | N21: =ROUNDUP(K21/31*320,0) -> 320 | O21: =N21*5 -> 1600 | P21: =N21+O21 -> 1920
A22: FAA | B22: 4320 | C22: FS | D22: Immar Karim | E22: 4700E720920 | F22: 43203-1564655-3 | H22: 37516 | I22: 45261 | K22: =MAX(0, MIN(M22, J22) - MAX(L22, I22) + 1) -> 31 | L22: 45261 | M22: 45291 | N22: =ROUNDUP(K22/31*320,0) -> 320 | O22: =N22*5 -> 1600 | P22: =N22+O22 -> 1920
A23: FAA | B23: 4320 | C23: FS | D23: Jalees Mukarram | E23: 4700G638367 | F23: 31201-9892348-9 | H23: 37210 | I23: 44125 | K23: =MAX(0, MIN(M23, J23) - MAX(L23, I23) + 1) -> 31 | L23: 45261 | M23: 45291 | N23: =ROUNDUP(K23/31*320,0) -> 320 | O23: =N23*5 -> 1600 | P23: =N23+O23 -> 1920
A24: FAA | B24: 4320 | C24: FS | D24: Khadija Umer | E24: 4700A710848 | F24: 31202-4982058-2 | H24: 36401 | I24: 45096 | K24: =MAX(0, MIN(M24, J24) - MAX(L24, I24) + 1) -> 31 | L24: 45261 | M24: 45291 | N24: =ROUNDUP(K24/31*320,0) -> 320 | O24: =N24*5 -> 1600 | P24: =N24+O24 -> 1920
A25: FAA | B25: 4320 | C25: FS | D25: Laiba Imran | E25: 4700H684977 | F25: 37405-8102020-8 | H25: 36113 | I25: 44866 | K25: =MAX(0, MIN(M25, J25) - MAX(L25, I25) + 1) -> 31 | L25: 45261 | M25: 45291 | N25: =ROUNDUP(K25/31*320,0) -> 320 | O25: =N25*5 -> 1600 | P25: =N25+O25 -> 1920
A26: FAA | B26: 4320 | C26: FS | D26: Mohammad Ehtasham Balland | E26: 4700D711914 | F26: 36302-5494206-1 | H26: 33737 | I26: 45139 | K26: =MAX(0, MIN(M26, J26) - MAX(L26, I26) + 1) -> 31 | L26: 45261 | M26: 45291 | N26: =ROUNDUP(K26/31*320,0) -> 320 | O26: =N26*5 -> 1600 | P26: =N26+O26 -> 1920
A27: FAA | B27: 4320 | C27: FS | D27: Muaaz Arshad | E27: 4100C164358 | F27: 34101-0197233-1 | H27: 33917 | I27: 45166 | K27: =MAX(0, MIN(M27, J27) - MAX(L27, I27) + 1) -> 31 | L27: 45261 | M27: 45291 | N27: =ROUNDUP(K27/31*320,0) -> 320 | O27: =N27*5 -> 1600 | P27: =N27+O27 -> 1920
... A55: FAA | B55: 4320 | C55: FS | D55: Shawal Fida | E55: 4700I700798 | F55: 16202-0438523-4 | H55: 36075 | I55: 44977 | K55: =MAX(0, MIN(M55, J55) - MAX(L55, I55) + 1) -> 31 | L55: 45261 | M55: 45291 | N55: =ROUNDUP(K55/31*320,0) -> 320 | O55: =N55*5 -> 1600 | P55: =N55+O55 -> 1920
A56: FAA | B56: 4320 | C56: FS | D56: Sheikh Muhammad Saad | E56: 3600D516452 | F56: 35202-2211437-9 | H56: 36089 | I56: 45195 | J56: 45282 | K56: =MAX(0, MIN(M56, J56) - MAX(L56, I56) + 1) -> 22 | L56: 45261 | M56: 45291 | N56: =ROUNDUP(K56/31*320,0) -> 228 | O56: =N56*5 -> 1140 | P56: =N56+O56 -> 1368
A57: FAA | B57: 4320 | C57: FS | D57: Subhana Yasin | E57: 4700E723960 | F57: 36502-1828819-0 | H57: 36574 | I57: 45187 | K57: =MAX(0, MIN(M57, J57) - MAX(L57, I57) + 1) -> 31 | L57: 45261 | M57: 45291 | N57: =ROUNDUP(K57/31*320,0) -> 320 | O57: =N57*5 -> 1600 | P57: =N57+O57 -> 1920
A58: FAA | B58: 4320 | C58: FS | D58: Talha Arshad Malik | E58: 3600F372686 | F58: 37405-6378563-1 | H58: 33156 | I58: 44285 | K58: =MAX(0, MIN(M58, J58) - MAX(L58, I58) + 1) -> 31 | L58: 45261 | M58: 45291 | N58: =ROUNDUP(K58/31*320,0) -> 320 | O58: =N58*5 -> 1600 | P58: =N58+O58 -> 1920
A59: FAA | B59: 4320 | C59: FS | D59: Tayyab Abbas | E59: 4700A685051 | F59: 17301-2752063-7 | H59: 36797 | I59: 44886 | K59: =MAX(0, MIN(M59, J59) - MAX(L59, I59) + 1) -> 31 | L59: 45261 | M59: 45291 | N59: =ROUNDUP(K59/31*320,0) -> 320 | O59: =N59*5 -> 1600 | P59: =N59+O59 -> 1920
A60: FAA | B60: 4320 | C60: FS | D60: Umaira Jabeen | E60: 3600J522091 | F60: 37104-5371430-8 | H60: 33769 | I60: 44816 | K60: =MAX(0, MIN(M60, J60) - MAX(L60, I60) + 1) -> 31 | L60: 45261 | M60: 45291 | N60: =ROUNDUP(K60/31*320,0) -> 320 | O60: =N60*5 -> 1600 | P60: =N60+O60 -> 1920
A61: FAA | B61: 4320 | C61: FS | D61: Umar Farooq | E61: 4700D723961 | F61: 36501-4241566-9 | H61: 36408 | I61: 45173 | K61: =MAX(0, MIN(M61, J61) - MAX(L61, I61) + 1) -> 31 | L61: 45261 | M61: 45291 | N61: =ROUNDUP(K61/31*320,0) -> 320 | O61: =N61*5 -> 1600 | P61: =N61+O61 -> 1920
A62: FAA | B62: 4320 | C62: FS | D62: Waleed Sadiq | E62: 4700C710870 | F62: 82101-6085499-3 | H62: 35818 | I62: 45089 | K62: =MAX(0, MIN(M62, J62) - MAX(L62, I62) + 1) -> 31 | L62: 45261 | M62: 45291 | N62: =ROUNDUP(K62/31*320,0) -> 320 | O62: =N62*5 -> 1600 | P62: =N62+O62 -> 1920
A63: FAA | B63: 4320 | C63: FS | D63: Zain Shahid | E63: 4700H700799 | F63: 36401-6591078-1 | H63: 36177 | I63: 44970 | J63: 45291 | K63: =MAX(0, MIN(M63, J63) - MAX(L63, I63) + 1) -> 31 | L63: 45261 | M63: 45291 | N63: =ROUNDUP(K63/31*320,0) -> 320 | O63: =N63*5 -> 1600 | P63: =N63+O63 -> 1920
A64: FAA | B64: 4320 | C64: FS | D64: Zoha Munir | E64: 0600G182381 | F64: 35202-9887337-8 | H64: 35743 | I64: 45222 | K64: =MAX(0, MIN(M64, J64) - MAX(L64, I64) + 1) -> 31 | L64: 45261 | M64: 45291 | N64: =ROUNDUP(K64/31*320,0) -> 320 | O64: =N64*5 -> 1600 | P64: =N64+O64 -> 1920
P65: =SUM(P2:P64) -> 117888

Sheet Jan-24
A1: EMP_AREA_CODE | B1: EMP_REG_SERIAL_NO | C1: EMP_SUB_AREA_CODE | D1: Name | E1: EOBI_NO | F1: CNIC | G1: NIC | H1: DOB | I1: DOJ | J1: DOE | K1: NO_OF_DAYS_WORKED | L1: From_Date | M1: To_Date | N1: Payment | O1: Employer Contribution | P1: Total EOBI
A2: FAA | B2: 4320 | C2: FS | D2: Abdul Hameed | E2: 4700J763957 | F2: 17301-6508006-1 | H2: 36617 | I2: 45299 | K2: =MAX(0, MIN(M2, J2) - MAX(L2, I2) + 1) -> 24 | L2: 45292 | M2: 45322 | N2: =ROUNDUP(K2/31*320,0) -> 248 | O2: =N2*5 -> 1240 | P2: =N2+O2 -> 1488
A3: FAA | B3: 4320 | C3: FS | D3: Abdullah Bin Rashid | E3: 4700A705194 | F3: 61101-3101618-7 | H3: 36358 | I3: 45027 | K3: =MAX(0, MIN(M3, J3) - MAX(L3, I3) + 1) -> 31 | L3: 45292 | M3: 45322 | N3: =ROUNDUP(K3/31*320,0) -> 320 | O3: =N3*5 -> 1600 | P3: =N3+O3 -> 1920
A4: FAA | B4: 4320 | C4: FS | D4: Abdullah Rasheed | E4: 4700G688671 | F4: 37401-7271621-7 | H4: 36860 | I4: 45124 | K4: =MAX(0, MIN(M4, J4) - MAX(L4, I4) + 1) -> 31 | L4: 45292 | M4: 45322 | N4: =ROUNDUP(K4/31*320,0) -> 320 | O4: =N4*5 -> 1600 | P4: =N4+O4 -> 1920
A5: FAA | B5: 4320 | C5: FS | D5: Ahmad Hassan | E5: 4600D315335 | F5: 37405-4246562-3 | H5: 35997 | I5: 45061 | K5: =MAX(0, MIN(M5, J5) - MAX(L5, I5) + 1) -> 31 | L5: 45292 | M5: 45322 | N5: =ROUNDUP(K5/31*320,0) -> 320 | O5: =N5*5 -> 1600 | P5: =N5+O5 -> 1920
A6: FAA | B6: 4320 | C6: FS | D6: Ahmed Hussain | E6: 4800F063920 | F6: 38102-5707136-9 | H6: 36353 | I6: 45278 | K6: =MAX(0, MIN(M6, J6) - MAX(L6, I6) + 1) -> 31 | L6: 45292 | M6: 45322 | N6: =ROUNDUP(K6/31*320,0) -> 320 | O6: =N6*5 -> 1600 | P6: =N6+O6 -> 1920
A7: FAA | B7: 4320 | C7: FS | D7: Ali Aziz | E7: 4700J723957 | F7: 81202-8426576-7 | H7: 35053 | I7: 45173 | J7: 45322 | K7: =MAX(0, MIN(M7, J7) - MAX(L7, I7) + 1) -> 31 | L7: 45292 | M7: 45322 | N7: =ROUNDUP(K7/31*320,0) -> 320 | O7: =N7*5 -> 1600 | P7: =N7+O7 -> 1920
A8: FAA | B8: 4320 | C8: FS | D8: Ali Irfan | E8: 3100J940197 | F8: 35202-7336402-9 | H8: 36634 | I8: 45251 | K8: =MAX(0, MIN(M8, J8) - MAX(L8, I8) + 1) -> 31 | L8: 45292 | M8: 45322 | N8: =ROUNDUP(K8/31*320,0) -> 320 | O8: =N8*5 -> 1600 | P8: =N8+O8 -> 1920
A9: FAA | B9: 4320 | C9: FS | D9: Ali Nawaz Channa | E9: 0800E397265 | F9: 42201-8465990-5 | H9: 33408 | I9: 45078 | K9: =MAX(0, MIN(M9, J9) - MAX(L9, I9) + 1) -> 31 | L9: 45292 | M9: 45322 | N9: =ROUNDUP(K9/31*320,0) -> 320 | O9: =N9*5 -> 1600 | P9: =N9+O9 -> 1920
A10: FAA | B10: 4320 | C10: FS | D10: Alina Mubarik | E10: 4700C710820 | F10: 61101-5318332-4 | H10: 35983 | I10: 45082 | K10: =MAX(0, MIN(M10, J10) - MAX(L10, I10) + 1) -> 31 | L10: 45292 | M10: 45322 | N10: =ROUNDUP(K10/31*320,0) -> 320 | O10: =N10*5 -> 1600 | P10: =N10+O10 -> 1920
A11: FAA | B11: 4320 | C11: FS | D11: Altamash Shaban | E11: 4700G469815 | F11: 37405-5322814-9 | H11: 33048 | I11: 45250 | K11: =MAX(0, MIN(M11, J11) - MAX(L11, I11) + 1) -> 31 | L11: 45292 | M11: 45322 | N11: =ROUNDUP(K11/31*320,0) -> 320 | O11: =N11*5 -> 1600 | P11: =N11+O11 -> 1920
A12: FAA | B12: 4320 | C12: FS | D12: Anamil Mehtab | E12: 4700A710822 | F12: 37103-6819266-4 | H12: 37398 | I12: 45292 | K12: =MAX(0, MIN(M12, J12) - MAX(L12, I12) + 1) -> 31 | L12: 45292 | M12: 45322 | N12: =ROUNDUP(K12/31*320,0) -> 320 | O12: =N12*5 -> 1600 | P12: =N12+O12 -> 1920
A13: FAA | B13: 4320 | C13: FS | D13: Asim Latif | E13: 4700A658224 | F13: 33302-5158556-5 | H13: 37370 | I13: 44739 | K13: =MAX(0, MIN(M13, J13) - MAX(L13, I13) + 1) -> 31 | L13: 45292 | M13: 45322 | N13: =ROUNDUP(K13/31*320,0) -> 320 | O13: =N13*5 -> 1600 | P13: =N13+O13 -> 1920
A14: FAA | B14: 4320 | C14: FS | D14: Atif Nawaz | E14: 4700E740695 | F14: 38404-7428636-7 | H14: 36399 | I14: 45229 | K14: =MAX(0, MIN(M14, J14) - MAX(L14, I14) + 1) -> 31 | L14: 45292 | M14: 45322 | N14: =ROUNDUP(K14/31*320,0) -> 320 | O14: =N14*5 -> 1600 | P14: =N14+O14 -> 1920
A15: FAA | B15: 4320 | C15: FS | D15: Basit Afraz | E15: 4700C703310 | F15: 37405-8019865-5 | H15: 34601 | I15: 44986 | K15: =MAX(0, MIN(M15, J15) - MAX(L15, I15) + 1) -> 31 | L15: 45292 | M15: 45322 | N15: =ROUNDUP(K15/31*320,0) -> 320 | O15: =N15*5 -> 1600 | P15: =N15+O15 -> 1920
A16: FAA | B16: 4320 | C16: FS | D16: Faiza Khan | E16: 4700J710823 | F16: 61101-0776147-2 | H16: 37322 | I16: 45096 | K16: =MAX(0, MIN(M16, J16) - MAX(L16, I16) + 1) -> 31 | L16: 45292 | M16: 45322 | N16: =ROUNDUP(K16/31*320,0) -> 320 | O16: =N16*5 -> 1600 | P16: =N16+O16 -> 1920
A17: FAA | B17: 4320 | C17: FS | D17: Faizan Khan | E17: 4700C662124 | F17: 16204-0388636-3 | H17: 35704 | I17: 44760 | K17: =MAX(0, MIN(M17, J17) - MAX(L17, I17) + 1) -> 31 | L17: 45292 | M17: 45322 | N17: =ROUNDUP(K17/31*320,0) -> 320 | O17: =N17*5 -> 1600 | P17: =N17+O17 -> 1920
A18: FAA | B18: 4320 | C18: FS | D18: Hamza Ahmad | E18: 4700I678608 | F18: 37405-6689341-9 | H18: 36246 | I18: 44851 | K18: =MAX(0, MIN(M18, J18) - MAX(L18, I18) + 1) -> 31 | L18: 45292 | M18: 45322 | N18: =ROUNDUP(K18/31*320,0) -> 320 | O18: =N18*5 -> 1600 | P18: =N18+O18 -> 1920
A19: FAA | B19: 4320 | C19: FS | D19: Hamza Ali Khan | E19: 4700B690429 | F19: 37405-5700118-7 | H19: 35606 | I19: 44896 | K19: =MAX(0, MIN(M19, J19) - MAX(L19, I19) + 1) -> 31 | L19: 45292 | M19: 45322 | N19: =ROUNDUP(K19/31*320,0) -> 320 | O19: =N19*5 -> 1600 | P19: =N19+O19 -> 1920
... A25: FAA | B25: 4320 | C25: FS | D25: Khadija Umer | E25: 4700A710848 | F25: 31202-4982058-2 | H25: 36401 | I25: 45096 | K25: =MAX(0, MIN(M25, J25) - MAX(L25, I25) + 1) -> 31 | L25: 45292 | M25: 45322 | N25: =ROUNDUP(K25/31*320,0) -> 320 | O25: =N25*5 -> 1600 | P25: =N25+O25 -> 1920
A26: FAA | B26: 4320 | C26: FS | D26: Laiba Imran | E26: 4700H684977 | F26: 37405-8102020-8 | H26: 36113 | I26: 44866 | J26: 45299 | K26: =MAX(0, MIN(M26, J26) - MAX(L26, I26) + 1) -> 8 | L26: 45292 | M26: 45322 | N26: =ROUNDUP(K26/31*320,0) -> 83 | O26: =N26*5 -> 415 | P26: =N26+O26 -> 498
A27: FAA | B27: 4320 | C27: FS | D27: Mirza Zain Ali Nasir | E27: 4700I764093 | F27: 35201-1057763-3 | H27: 36769 | I27: 45313 | J27: 45415 | K27: =MAX(0, MIN(M27, J27) - MAX(L27, I27) + 1) -> 10 | L27: 45292 | M27: 45322 | N27: =ROUNDUP(K27/31*320,0) -> 104 | O27: =N27*5 -> 520 | P27: =N27+O27 -> 624
A28: FAA | B28: 4320 | C28: FS | D28: Mohammad Ehtasham Balland | E28: 4700D711914 | F28: 36302-5494206-1 | H28: 33737 | I28: 45139 | K28: =MAX(0, MIN(M28, J28) - MAX(L28, I28) + 1) -> 31 | L28: 45292 | M28: 45322 | N28: =ROUNDUP(K28/31*320,0) -> 320 | O28: =N28*5 -> 1600 | P28: =N28+O28 -> 1920
A29: FAA | B29: 4320 | C29: FS | D29: Muaaz Arshad | E29: 4100C164358 | F29: 34101-0197233-1 | H29: 33917 | I29: 45166 | J29: 45321 | K29: =MAX(0, MIN(M29, J29) - MAX(L29, I29) + 1) -> 30 | L29: 45292 | M29: 45322 | N29: =ROUNDUP(K29/31*320,0) -> 310 | O29: =N29*5 -> 1550 | P29: =N29+O29 -> 1860
A30: FAA | B30: 4320 | C30: FS | D30: Muhammad Abdullah Salam | E30: 4700G697010 | F30: 17301-7752570-9 | H30: 36690 | I30: 44938 | K30: =MAX(0, MIN(M30, J30) - MAX(L30, I30) + 1) -> 31 | L30: 45292 | M30: 45322 | N30: =ROUNDUP(K30/31*320,0) -> 320 | O30: =N30*5 -> 1600 | P30: =N30+O30 -> 1920
A31: FAA | B31: 4320 | C31: FS | D31: Muhammad Abubakar | E31: 4700H723959 | F31: 35201-8046049-1 | H31: 37240 | I31: 45176 | K31: =MAX(0, MIN(M31, J31) - MAX(L31, I31) + 1) -> 31 | L31: 45292 | M31: 45322 | N31: =ROUNDUP(K31/31*320,0) -> 320 | O31: =N31*5 -> 1600 | P31: =N31+O31 -> 1920
A32: FAA | B32: 4320 | C32: FS | D32: Muhammad Ali Kiyani | E32: 4700I483207 | F32: 61101-7478749-3 | H32: 35173 | I32: 45264 | K32: =MAX(0, MIN(M32, J32) - MAX(L32, I32) + 1) -> 31 | L32: 45292 | M32: 45322 | N32: =ROUNDUP(K32/31*320,0) -> 320 | O32: =N32*5 -> 1600 | P32: =N32+O32 -> 1920
A33: FAA | B33: 4320 | C33: FS | D33: Muhammad Arham | E33: 4700J673932 | F33: 36103-7439746-1 | H33: 37136 | I33: 45201 | K33: =MAX(0, MIN(M33, J33) - MAX(L33, I33) + 1) -> 31 | L33: 45292 | M33: 45322 | N33: =ROUNDUP(K33/31*320,0) -> 320 | O33: =N33*5 -> 1600 | P33: =N33+O33 -> 1920
A34: FAA | B34: 4320 | C34: FS | D34: Muhammad Asadullah Shahid | E34: 4700G581544 | F34: 36603-1234883-1 | H34: 35943 | I34: 45215 | K34: =MAX(0, MIN(M34, J34) - MAX(L34, I34) + 1) -> 31 | L34: 45292 | M34: 45322 | N34: =ROUNDUP(K34/31*320,0) -> 320 | O34: =N34*5 -> 1600 | P34: =N34+O34 -> 1920
A35: FAA | B35: 4320 | C35: FS | D35: Muhammad Hammad Maqsood | E35: 4700A703312 | F35: 37405-2794891-9 | H35: 36898 | I35: 44988 | K35: =MAX(0, MIN(M35, J35) - MAX(L35, I35) + 1) -> 31 | L35: 45292 | M35: 45322 | N35: =ROUNDUP(K35/31*320,0) -> 320 | O35: =N35*5 -> 1600 | P35: =N35+O35 -> 1920
A36: FAA | B36: 4320 | C36: FS | D36: Muhammad Hamza | E36: 4600F317513 | F36: 61101-4668132-7 | H36: 35159 | I36: 45078 | J36: 45322 | K36: =MAX(0, MIN(M36, J36) - MAX(L36, I36) + 1) -> 31 | L36: 45292 | M36: 45322 | N36: =ROUNDUP(K36/31*320,0) -> 320 | O36: =N36*5 -> 1600 | P36: =N36+O36 -> 1920
A37: FAA | B37: 4320 | C37: FS | D37: Muhammad Hassan Shakeel | E37: 4700H690431 | F37: 35402-2593513-5 | H37: 36794 | I37: 44915 | K37: =MAX(0, MIN(M37, J37) - MAX(L37, I37) + 1) -> 31 | L37: 45292 | M37: 45322 | N37: =ROUNDUP(K37/31*320,0) -> 320 | O37: =N37*5 -> 1600 | P37: =N37+O37 -> 1920
A38: FAA | B38: 4320 | C38: FS | D38: Muhammad Ibrahim | E38: 4700C720948 | F38: 31101-0776303-7 | H38: 37149 | I38: 45124 | K38: =MAX(0, MIN(M38, J38) - MAX(L38, I38) + 1) -> 31 | L38: 45292 | M38: 45322 | N38: =ROUNDUP(K38/31*320,0) -> 320 | O38: =N38*5 -> 1600 | P38: =N38+O38 -> 1920
A39: FAA | B39: 4320 | C39: FS | D39: Muhammad Nabeel Asif | E39: 0800I431358 | F39: 42101-1217952-3 | H39: 34503 | I39: 45246 | J39: 45338 | K39: =MAX(0, MIN(M39, J39) - MAX(L39, I39) + 1) -> 31 | L39: 45292 | M39: 45322 | N39: =ROUNDUP(K39/31*320,0) -> 320 | O39: =N39*5 -> 1600 | P39: =N39+O39 -> 1920
A40: FAA | B40: 4320 | C40: FS | D40: Muhammad Saad Tariq | E40: 4700D679730 | F40: 61101-0817777-7 | H40: 36207 | I40: 45054 | K40: =MAX(0, MIN(M40, J40) - MAX(L40, I40) + 1) -> 31 | L40: 45292 | M40: 45322 | N40: =ROUNDUP(K40/31*320,0) -> 320 | O40: =N40*5 -> 1600 | P40: =N40+O40 -> 1920
A41: FAA | B41: 4320 | C41: FS | D41: Muhammad Zahab Ahmed | E41: 3600G329844 | F41: 31102-2135283-9 | H41: 34300 | I41: 45183 | K41: =MAX(0, MIN(M41, J41) - MAX(L41, I41) + 1) -> 31 | L41: 45292 | M41: 45322 | N41: =ROUNDUP(K41/31*320,0) -> 320 | O41: =N41*5 -> 1600 | P41: =N41+O41 -> 1920
A42: FAA | B42: 4320 | C42: FS | D42: Naimal Imran | E42: 4700J662127 | F42: 35202-0754928-4 | H42: 36541 | I42: 44755 | K42: =MAX(0, MIN(M42, J42) - MAX(L42, I42) + 1) -> 31 | L42: 45292 | M42: 45322 | N42: =ROUNDUP(K42/31*320,0) -> 320 | O42: =N42*5 -> 1600 | P42: =N42+O42 -> 1920
A43: FAA | B43: 4320 | C43: FS | D43: Namra Akram | E43: 4700F444303 | F43: 61101-4919576-8 | H43: 34335 | I43: 45078 | K43: =MAX(0, MIN(M43, J43) - MAX(L43, I43) + 1) -> 31 | L43: 45292 | M43: 45322 | N43: =ROUNDUP(K43/31*320,0) -> 320 | O43: =N43*5 -> 1600 | P43: =N43+O43 -> 1920
A44: FAA | B44: 4320 | C44: FS | D44: Naveed Ahmed | E44: 4700H679736 | F44: 42201-5462974-9 | H44: 31014 | I44: 44805 | K44: =MAX(0, MIN(M44, J44) - MAX(L44, I44) + 1) -> 31 | L44: 45292 | M44: 45322 | N44: =ROUNDUP(K44/31*320,0) -> 320 | O44: =N44*5 -> 1600 | P44: =N44+O44 -> 1920
A45: FAA | B45: 4320 | C45: FS | D45: Nimra Zahid | E45: 4700G537391 | F45: 42201-1439506-4 | H45: 34522 | I45: 45292 | K45: =MAX(0, MIN(M45, J45) - MAX(L45, I45) + 1) -> 31 | L45: 45292 | M45: 45322 | N45: =ROUNDUP(K45/31*320,0) -> 320 | O45: =N45*5 -> 1600 | P45: =N45+O45 -> 1920
...

Sheet Feb-24
A1: EMP_AREA_CODE | B1: EMP_REG_SERIAL_NO | C1: EMP_SUB_AREA_CODE | D1: Name | E1: EOBI_NO | F1: CNIC | G1: NIC | H1: DOB | I1: DOJ | J1: DOE | K1: NO_OF_DAYS_WORKED | L1: From_Date | M1: To_Date | N1: Payment | O1: Employer Contribution | P1: Total EOBI
A2: FAA | B2: 4320 | C2: FS | D2: Abdul Hameed | E2: 4700J763957 | F2: 17301-6508006-1 | H2: 36617 | I2: 45299 | K2: =MAX(0, MIN(M2, J2) - MAX(L2, I2) + 1) -> 29 | L2: 45323 | M2: 45351 | N2: =ROUNDUP(K2/29*320,0) -> 320 | O2: =N2*5 -> 1600 | P2: =N2+O2 -> 1920
A3: FAA | B3: 4320 | C3: FS | D3: Abdullah Bin Rashid | E3: 4700A705194 | F3: 61101-3101618-7 | H3: 36358 | I3: 45027 | K3: =MAX(0, MIN(M3, J3) - MAX(L3, I3) + 1) -> 29 | L3: 45323 | M3: 45351 | N3: =ROUNDUP(K3/29*320,0) -> 320 | O3: =N3*5 -> 1600 | P3: =N3+O3 -> 1920
A4: FAA | B4: 4320 | C4: FS | D4: Abdullah Rasheed | E4: 4700G688671 | F4: 37401-7271621-7 | H4: 36860 | I4: 45124 | K4: =MAX(0, MIN(M4, J4) - MAX(L4, I4) + 1) -> 29 | L4: 45323 | M4: 45351 | N4: =ROUNDUP(K4/29*320,0) -> 320 | O4: =N4*5 -> 1600 | P4: =N4+O4 -> 1920
A5: FAA | B5: 4320 | C5: FS | D5: Ahmad Hassan | E5: 4600D315335 | F5: 37405-4246562-3 | H5: 35997 | I5: 45061 | K5: =MAX(0, MIN(M5, J5) - MAX(L5, I5) + 1) -> 29 | L5: 45323 | M5: 45351 | N5: =ROUNDUP(K5/29*320,0) -> 320 | O5: =N5*5 -> 1600 | P5: =N5+O5 -> 1920
A6: FAA | B6: 4320 | C6: FS | D6: Ahmed Hussain | E6: 4800F063920 | F6: 38102-5707136-9 | H6: 36353 | I6: 45278 | K6: =MAX(0, MIN(M6, J6) - MAX(L6, I6) + 1) -> 29 | L6: 45323 | M6: 45351 | N6: =ROUNDUP(K6/29*320,0) -> 320 | O6: =N6*5 -> 1600 | P6: =N6+O6 -> 1920
A7: FAA | B7: 4320 | C7: FS | D7: Ali Irfan | E7: 3100J940197 | F7: 35202-7336402-9 | H7: 36634 | I7: 45251 | K7: =MAX(0, MIN(M7, J7) - MAX(L7, I7) + 1) -> 29 | L7: 45323 | M7: 45351 | N7: =ROUNDUP(K7/29*320,0) -> 320 | O7: =N7*5 -> 1600 | P7: =N7+O7 -> 1920
A8: FAA | B8: 4320 | C8: FS | D8: Ali Nawaz Channa | E8: 0800E397265 | F8: 42201-8465990-5 | H8: 33408 | I8: 45078 | K8: =MAX(0, MIN(M8, J8) - MAX(L8, I8) + 1) -> 29 | L8: 45323 | M8: 45351 | N8: =ROUNDUP(K8/29*320,0) -> 320 | O8: =N8*5 -> 1600 | P8: =N8+O8 -> 1920
A9: FAA | B9: 4320 | C9: FS | D9: Alina Mubarik | E9: 4700C710820 | F9: 61101-5318332-4 | H9: 35983 | I9: 45082 | K9: =MAX(0, MIN(M9, J9) - MAX(L9, I9) + 1) -> 29 | L9: 45323 | M9: 45351 | N9: =ROUNDUP(K9/29*320,0) -> 320 | O9: =N9*5 -> 1600 | P9: =N9+O9 -> 1920
A10: FAA | B10: 4320 | C10: FS | D10: Altamash Shaban | E10: 4700G469815 | F10: 37405-5322814-9 | H10: 33048 | I10: 45250 | J10: 45329 | K10: =MAX(0, MIN(M10, J10) - MAX(L10, I10) + 1) -> 7 | L10: 45323 | M10: 45351 | N10: =ROUNDUP(K10/29*320,0) -> 78 | O10: =N10*5 -> 390 | P10: =N10+O10 -> 468
A11: FAA | B11: 4320 | C11: FS | D11: Anamil Mehtab | E11: 4700A710822 | F11: 37103-6819266-4 | H11: 37398 | I11: 45096 | K11: =MAX(0, MIN(M11, J11) - MAX(L11, I11) + 1) -> 29 | L11: 45323 | M11: 45351 | N11: =ROUNDUP(K11/29*320,0) -> 320 | O11: =N11*5 -> 1600 | P11: =N11+O11 -> 1920
A12: FAA | B12: 4320 | C12: FS | D12: Asad Ullah | E12: 4700C748792 | F12: 34401-8557347-3 | H12: 35047 | I12: 45257 | K12: =MAX(0, MIN(M12, J12) - MAX(L12, I12) + 1) -> 29 | L12: 45323 | M12: 45351 | N12: =ROUNDUP(K12/29*320,0) -> 320 | O12: =N12*5 -> 1600 | P12: =N12+O12 -> 1920
A13: FAA | B13: 4320 | C13: FS | D13: Asim Latif | E13: 4700A658224 | F13: 33302-5158556-5 | H13: 37370 | I13: 44739 | K13: =MAX(0, MIN(M13, J13) - MAX(L13, I13) + 1) -> 29 | L13: 45323 | M13: 45351 | N13: =ROUNDUP(K13/29*320,0) -> 320 | O13: =N13*5 -> 1600 | P13: =N13+O13 -> 1920
A14: FAA | B14: 4320 | C14: FS | D14: Atif Nawaz | E14: 4700E740695 | F14: 38404-7428636-7 | H14: 36399 | I14: 45229 | K14: =MAX(0, MIN(M14, J14) - MAX(L14, I14) + 1) -> 29 | L14: 45323 | M14: 45351 | N14: =ROUNDUP(K14/29*320,0) -> 320 | O14: =N14*5 -> 1600 | P14: =N14+O14 -> 1920
A15: FAA | B15: 4320 | C15: FS | D15: Ayesha Syed | E15: 4700E763960 | F15: 37405-5537896-0 | H15: 37377 | I15: 45334 | K15: =MAX(0, MIN(M15, J15) - MAX(L15, I15) + 1) -> 18 | L15: 45323 | M15: 45351 | N15: =ROUNDUP(K15/29*320,0) -> 199 | O15: =N15*5 -> 995 | P15: =N15+O15 -> 1194
A16: FAA | B16: 4320 | C16: FS | D16: Ayesha Tahir | E16: 4700A748794 | F16: 13101-5843018-0 | H16: 37047 | I16: 45257 | K16: =MAX(0, MIN(M16, J16) - MAX(L16, I16) + 1) -> 29 | L16: 45323 | M16: 45351 | N16: =ROUNDUP(K16/29*320,0) -> 320 | O16: =N16*5 -> 1600 | P16: =N16+O16 -> 1920
A17: FAA | B17: 4320 | C17: FS | D17: Basit Afraz | E17: 4700C703310 | F17: 37405-8019865-5 | H17: 34601 | I17: 44986 | K17: =MAX(0, MIN(M17, J17) - MAX(L17, I17) + 1) -> 29 | L17: 45323 | M17: 45351 | N17: =ROUNDUP(K17/29*320,0) -> 320 | O17: =N17*5 -> 1600 | P17: =N17+O17 -> 1920
A18: FAA | B18: 4320 | C18: FS | D18: Faiza Khan | E18: 4700J710823 | F18: 61101-0776147-2 | H18: 37322 | I18: 45096 | K18: =MAX(0, MIN(M18, J18) - MAX(L18, I18) + 1) -> 29 | L18: 45323 | M18: 45351 | N18: =ROUNDUP(K18/29*320,0) -> 320 | O18: =N18*5 -> 1600 | P18: =N18+O18 -> 1920
A19: FAA | B19: 4320 | C19: FS | D19: Faizan Khan | E19: 4700C662124 | F19: 16204-0388636-3 | H19: 35704 | I19: 44760 | K19: =MAX(0, MIN(M19, J19) - MAX(L19, I19) + 1) -> 29 | L19: 45323 | M19: 45351 | N19: =ROUNDUP(K19/29*320,0) -> 320 | O19: =N19*5 -> 1600 | P19: =N19+O19 -> 1920
A20: FAA | B20: 4320 | C20: FS | D20: Farzam Habib Khan | E20: 4700B748793 | F20: 12101-9669033-4 | H20: 37219 | I20: 45257 | K20: =MAX(0, MIN(M20, J20) - MAX(L20, I20) + 1) -> 29 | L20: 45323 | M20: 45351 | N20: =ROUNDUP(K20/29*320,0) -> 320 | O20: =N20*5 -> 1600 | P20: =N20+O20 -> 1920
A21: FAA | B21: 4320 | C21: FS | D21: Hamza Ahmad | E21: 4700I678608 | F21: 37405-6689341-9 | H21: 36246 | I21: 44851 | K21: =MAX(0, MIN(M21, J21) - MAX(L21, I21) + 1) -> 29 | L21: 45323 | M21: 45351 | N21: =ROUNDUP(K21/29*320,0) -> 320 | O21: =N21*5 -> 1600 | P21: =N21+O21 -> 1920
A22: FAA | B22: 4320 | C22: FS | D22: Hamza Ali Khan | E22: 4700B690429 | F22: 37405-5700118-7 | H22: 35606 | I22: 44896 | K22: =MAX(0, MIN(M22, J22) - MAX(L22, I22) + 1) -> 29 | L22: 45323 | M22: 45351 | N22: =ROUNDUP(K22/29*320,0) -> 320 | O22: =N22*5 -> 1600 | P22: =N22+O22 -> 1920
... A41: FAA | B41: 4320 | C41: FS | D41: Muhammad Ibrahim | E41: 4700C720948 | F41: 31101-0776303-7 | H41: 37149 | I41: 45124 | K41: =MAX(0, MIN(M41, J41) - MAX(L41, I41) + 1) -> 29 | L41: 45323 | M41: 45351 | N41: =ROUNDUP(K41/29*320,0) -> 320 | O41: =N41*5 -> 1600 | P41: =N41+O41 -> 1920
A42: FAA | B42: 4320 | C42: FS | D42: Muhammad Nabeel Asif | E42: 0800I431358 | F42: 42101-1217952-3 | H42: 34503 | I42: 45246 | J42: 45338 | K42: =MAX(0, MIN(M42, J42) - MAX(L42, I42) + 1) -> 16 | L42: 45323 | M42: 45351 | N42: =ROUNDUP(K42/29*320,0) -> 177 | O42: =N42*5 -> 885 | P42: =N42+O42 -> 1062
A43: FAA | B43: 4320 | C43: FS | D43: Muhammad Saad Tariq | E43: 4700D679730 | F43: 61101-0817777-7 | H43: 36207 | I43: 45054 | J43: 45351 | K43: =MAX(0, MIN(M43, J43) - MAX(L43, I43) + 1) -> 29 | L43: 45323 | M43: 45351 | N43: =ROUNDUP(K43/29*320,0) -> 320 | O43: =N43*5 -> 1600 | P43: =N43+O43 -> 1920
A44: FAA | B44: 4320 | C44: FS | D44: Muhammad Zahab Ahmed | E44: 3600G329844 | F44: 31102-2135283-9 | H44: 34300 | I44: 45183 | K44: =MAX(0, MIN(M44, J44) - MAX(L44, I44) + 1) -> 29 | L44: 45323 | M44: 45351 | N44: =ROUNDUP(K44/29*320,0) -> 320 | O44: =N44*5 -> 1600 | P44: =N44+O44 -> 1920
A45: FAA | B45: 4320 | C45: FS | D45: Musa Naqvi
A46: FAA | B46: 4320 | C46: FS | D46: Naimal Imran | E46: 4700J662127 | F46: 35202-0754928-4 | H46: 36541 | I46: 44755 | K46: =MAX(0, MIN(M46, J46) - MAX(L46, I46) + 1) -> 29 | L46: 45323 | M46: 45351 | N46: =ROUNDUP(K46/29*320,0) -> 320 | O46: =N46*5 -> 1600 | P46: =N46+O46 -> 1920
A47: FAA | B47: 4320 | C47: FS | D47: Namra Akram | E47: 4700F444303 | F47: 61101-4919576-8 | H47: 34335 | I47: 45078 | K47: =MAX(0, MIN(M47, J47) - MAX(L47, I47) + 1) -> 29 | L47: 45323 | M47: 45351 | N47: =ROUNDUP(K47/29*320,0) -> 320 | O47: =N47*5 -> 1600 | P47: =N47+O47 -> 1920
A48: FAA | B48: 4320 | C48: FS | D48: Naveed Ahmed | E48: 4700H679736 | F48: 42201-5462974-9 | H48: 31014 | I48: 44805 | K48: =MAX(0, MIN(M48, J48) - MAX(L48, I48) + 1) -> 29 | L48: 45323 | M48: 45351 | N48: =ROUNDUP(K48/29*320,0) -> 320 | O48: =N48*5 -> 1600 | P48: =N48+O48 -> 1920
A49: FAA | B49: 4320 | C49: FS | D49: Nimra Zahid | E49: 4700G537391 | F49: 42201-1439506-4 | H49: 34522 | I49: 45292 | K49: =MAX(0, MIN(M49, J49) - MAX(L49, I49) + 1) -> 29 | L49: 45323 | M49: 45351 | N49: =ROUNDUP(K49/29*320,0) -> 320 | O49: =N49*5 -> 1600 | P49: =N49+O49 -> 1920
A50: FAA | B50: 4320 | C50: FS | D50: Rashid Iqbal | E50: 4700I703314 | F50: 37405-6880780-7 | H50: 34732 | I50: 44986 | K50: =MAX(0, MIN(M50, J50) - MAX(L50, I50) + 1) -> 29 | L50: 45323 | M50: 45351 | N50: =ROUNDUP(K50/29*320,0) -> 320 | O50: =N50*5 -> 1600 | P50: =N50+O50 -> 1920
A51: FAA | B51: 4320 | C51: FS | D51: Saad Ahmed | E51: 0800E406072 | F51: 35202-3107480-5 | H51: 33762 | I51: 45229 | K51: =MAX(0, MIN(M51, J51) - MAX(L51, I51) + 1) -> 31 | L51: 45261 | M51: 45291 | N51: =ROUNDUP(K51/31*320,0) -> 320 | O51: =N51*5 -> 1600 | P51: =N51+O51 -> 1920
A52: FAA | B52: 4320 | C52: FS | D52: Saif Ullah | E52: 4700A764083 | F52: 61101-5764361-9 | H52: 37479 | I52: 45320 | K52: =MAX(0, MIN(M52, J52) - MAX(L52, I52) + 1) -> 29 | L52: 45323 | M52: 45351 | N52: =ROUNDUP(K52/29*320,0) -> 320 | O52: =N52*5 -> 1600 | P52: =N52+O52 -> 1920
A53: FAA | B53: 4320 | C53: FS | D53: Salman Khalid | E53: 3300B264525 | F53: 34603-0435168-5 | H53: 33003 | I53: 45313 | K53: =MAX(0, MIN(M53, J53) - MAX(L53, I53) + 1) -> 29 | L53: 45323 | M53: 45351 | N53: =ROUNDUP(K53/29*320,0) -> 320 | O53: =N53*5 -> 1600 | P53: =N53+O53 -> 1920
A54: FAA | B54: 4320 | C54: FS | D54: Sana Sajjad Chaudhary | E54: 4700F740694 | F54: 37301-3885164-8 | H54: 36109 | I54: 45250 | K54: =MAX(0, MIN(M54, J54) - MAX(L54, I54) + 1) -> 29 | L54: 45323 | M54: 45351 | N54: =ROUNDUP(K54/29*320,0) -> 320 | O54: =N54*5 -> 1600 | P54: =N54+O54 -> 1920
A55: FAA | B55: 4320 | C55: FS | D55: Sana Tahir | E55: 4700D706561 | F55: 37103-2235902-2 | H55: 35976 | I55: 45042 | K55: =MAX(0, MIN(M55, J55) - MAX(L55, I55) + 1) -> 29 | L55: 45323 | M55: 45351 | N55: =ROUNDUP(K55/29*320,0) -> 320 | O55: =N55*5 -> 1600 | P55: =N55+O55 -> 1920
A56: FAA | B56: 4320 | C56: FS | D56: Shahnoor Ejaz | E56: 4700F703333 | F56: 42501-6125083-4 | H56: 36297 | I56: 45001 | K56: =MAX(0, MIN(M56, J56) - MAX(L56, I56) + 1) -> 29 | L56: 45323 | M56: 45351 | N56: =ROUNDUP(K56/29*320,0) -> 320 | O56: =N56*5 -> 1600 | P56: =N56+O56 -> 1920
A57: FAA | B57: 4320 | C57: FS | D57: Shahzad Farooq | E57: 4700G690432 | F57: 42501-8133748-7 | H57: 36979 | I57: 44907 | K57: =MAX(0, MIN(M57, J57) - MAX(L57, I57) + 1) -> 29 | L57: 45323 | M57: 45351 | N57: =ROUNDUP(K57/29*320,0) -> 320 | O57: =N57*5 -> 1600 | P57: =N57+O57 -> 1920
A58: FAA | B58: 4320 | C58: FS | D58: Shaiq Habib | E58: 0400C579124 | F58: 61101-1388832-7 | H58: 36421 | I58: 45208 | K58: =MAX(0, MIN(M58, J58) - MAX(L58, I58) + 1) -> 29 | L58: 45323 | M58: 45351 | N58: =ROUNDUP(K58/29*320,0) -> 320 | O58: =N58*5 -> 1600 | P58: =N58+O58 -> 1920
...

Sheet Mar-24
A1: EMP_AREA_CODE | B1: EMP_REG_SERIAL_NO | C1: EMP_SUB_AREA_CODE | D1: Name | E1: EOBI_NO | F1: CNIC | G1: NIC | H1: DOB | I1: DOJ | J1: DOE | K1: NO_OF_DAYS_WORKED | L1: From_Date | M1: To_Date | N1: Payment | O1: Employer Contribution | P1: Total EOBI
A2: FAA | B2: 4320 | C2: FS | D2: Abdul Hameed | E2: 4700J763957 | F2: 17301-6508006-1 | H2: 36617 | I2: 45299 | K2: =MAX(0, MIN(M2, J2) - MAX(L2, I2) + 1) -> 31 | L2: 45352 | M2: 45382 | N2: =ROUNDUP(K2/31*320,0) -> 320 | O2: =N2*5 -> 1600 | P2: =N2+O2 -> 1920
A3: FAA | B3: 4320 | C3: FS | D3: Abdul Rehan Najam | E3: 4700H764086 | F3: 61101-8333683-7 | H3: 37282 | I3: 45362 | K3: =MAX(0, MIN(M3, J3) - MAX(L3, I3) + 1) -> 21 | L3: 45352 | M3: 45382 | N3: =ROUNDUP(K3/31*320,0) -> 217 | O3: =N3*5 -> 1085 | P3: =N3+O3 -> 1302
A4: FAA | B4: 4320 | C4: FS | D4: Abdullah Bin Rashid | E4: 4700A705194 | F4: 61101-3101618-7 | H4: 36358 | I4: 45027 | K4: =MAX(0, MIN(M4, J4) - MAX(L4, I4) + 1) -> 31 | L4: 45352 | M4: 45382 | N4: =ROUNDUP(K4/31*320,0) -> 320 | O4: =N4*5 -> 1600 | P4: =N4+O4 -> 1920
A5: FAA | B5: 4320 | C5: FS | D5: Abdullah Rasheed | E5: 4700G688671 | F5: 37401-7271621-7 | H5: 36860 | I5: 45124 | K5: =MAX(0, MIN(M5, J5) - MAX(L5, I5) + 1) -> 31 | L5: 45352 | M5: 45382 | N5: =ROUNDUP(K5/31*320,0) -> 320 | O5: =N5*5 -> 1600 | P5: =N5+O5 -> 1920
A6: FAA | B6: 4320 | C6: FS | D6: Abu Usama | E6: 4700G764087 | F6: 36501-7651414-9 | H6: 35619 | I6: 45369 | K6: =MAX(0, MIN(M6, J6) - MAX(L6, I6) + 1) -> 14 | L6: 45352 | M6: 45382 | N6: =ROUNDUP(K6/31*320,0) -> 145 | O6: =N6*5 -> 725 | P6: =N6+O6 -> 870
A7: FAA | B7: 4320 | C7: FS | D7: Ahmad Hassan | E7: 4600D315335 | F7: 37405-4246562-3 | H7: 35997 | I7: 45061 | K7: =MAX(0, MIN(M7, J7) - MAX(L7, I7) + 1) -> 31 | L7: 45352 | M7: 45382 | N7: =ROUNDUP(K7/31*320,0) -> 320 | O7: =N7*5 -> 1600 | P7: =N7+O7 -> 1920
A8: FAA | B8: 4320 | C8: FS | D8: Ahmed Hussain | E8: 4800F063920 | F8: 38102-5707136-9 | H8: 36353 | I8: 45278 | K8: =MAX(0, MIN(M8, J8) - MAX(L8, I8) + 1) -> 31 | L8: 45352 | M8: 45382 | N8: =ROUNDUP(K8/31*320,0) -> 320 | O8: =N8*5 -> 1600 | P8: =N8+O8 -> 1920
A9: FAA | B9: 4320 | C9: FS | D9: Ali Irfan | E9: 3100J940197 | F9: 35202-7336402-9 | H9: 36634 | I9: 45251 | K9: =MAX(0, MIN(M9, J9) - MAX(L9, I9) + 1) -> 31 | L9: 45352 | M9: 45382 | N9: =ROUNDUP(K9/31*320,0) -> 320 | O9: =N9*5 -> 1600 | P9: =N9+O9 -> 1920
A10: FAA | B10: 4320 | C10: FS | D10: Ali Nawaz Channa | E10: 0800E397265 | F10: 42201-8465990-5 | H10: 33408 | I10: 45078 | J10: 45366 | K10: =MAX(0, MIN(M10, J10) - MAX(L10, I10) + 1) -> 15 | L10: 45352 | M10: 45382 | N10: =ROUNDUP(K10/31*320,0) -> 155 | O10: =N10*5 -> 775 | P10: =N10+O10 -> 930
A11: FAA | B11: 4320 | C11: FS | D11: Alina Mubarik | E11: 4700C710820 | F11: 61101-5318332-4 | H11: 35983 | I11: 45082 | J11: 45362 | K11: =MAX(0, MIN(M11, J11) - MAX(L11, I11) + 1) -> 11 | L11: 45352 | M11: 45382 | N11: =ROUNDUP(K11/31*320,0) -> 114 | O11: =N11*5 -> 570 | P11: =N11+O11 -> 684
A12: FAA | B12: 4320 | C12: FS | D12: Amish Tufail | E12: 4700H764094 | F12: 13302-2902324-3 | H12: 37274 | I12: 45362 | K12: =MAX(0, MIN(M12, J12) - MAX(L12, I12) + 1) -> 21 | L12: 45352 | M12: 45382 | N12: =ROUNDUP(K12/31*320,0) -> 217 | O12: =N12*5 -> 1085 | P12: =N12+O12 -> 1302
A13: FAA | B13: 4320 | C13: FS | D13: Anamil Mehtab | E13: 4700A710822 | F13: 37103-6819266-4 | H13: 37398 | I13: 45096 | K13: =MAX(0, MIN(M13, J13) - MAX(L13, I13) + 1) -> 31 | L13: 45352 | M13: 45382 | N13: =ROUNDUP(K13/31*320,0) -> 320 | O13: =N13*5 -> 1600 | P13: =N13+O13 -> 1920
A14: FAA | B14: 4320 | C14: FS | D14: Anas Hanif Attas | E14: 4700B665806 | F14: 38403-3251146-3 | H14: 36360 | I14: 45355 | K14: =MAX(0, MIN(M14, J14) - MAX(L14, I14) + 1) -> 28 | L14: 45352 | M14: 45382 | N14: =ROUNDUP(K14/31*320,0) -> 290 | O14: =N14*5 -> 1450 | P14: =N14+O14 -> 1740
A15: FAA | B15: 4320 | C15: FS | D15: Arsal Sher Khan | E15: 4700F764096 | F15: 35201-5498096-5 | H15: 37100 | I15: 45376 | K15: =MAX(0, MIN(M15, J15) - MAX(L15, I15) + 1) -> 7 | L15: 45352 | M15: 45382 | N15: =ROUNDUP(K15/31*320,0) -> 73 | O15: =N15*5 -> 365 | P15: =N15+O15 -> 438
A16: FAA | B16: 4320 | C16: FS | D16: Asad Ullah | E16: 4700C748792 | F16: 34401-8557347-3 | H16: 35047 | I16: 45257 | K16: =MAX(0, MIN(M16, J16) - MAX(L16, I16) + 1) -> 31 | L16: 45352 | M16: 45382 | N16: =ROUNDUP(K16/31*320,0) -> 320 | O16: =N16*5 -> 1600 | P16: =N16+O16 -> 1920
